Workbook
Name sector: INDUSTRYGROUP!$C$1:$D$23

Sheet SUBINDUSTRY
A1: SUBINDUSTRY CODE | B1: SUBINDUSTRY | C1: INDUSTRY CODE | D1: INDUSTRY
A2: 0111 | B2: Growing of cereals (except rice), leguminous crops and oil seeds | C2: 011 | D2: Growing of non-perennial crops
A3: 0112 | B3: Growing of rice | C3: 011 | D3: Growing of non-perennial crops
A4: 0113 | B4: Growing of vegetables and melons, roots and tubers | C4: 011 | D4: Growing of non-perennial crops
A5: 0114 | B5: Growing of sugar cane | C5: 011 | D5: Growing of non-perennial crops
A6: 0115 | B6: Growing of tobacco | C6: 011 | D6: Growing of non-perennial crops
A7: 0116 | B7: Growing of fibre crops | C7: 011 | D7: Growing of non-perennial crops
A8: 0119 | B8: Growing of other non-perennial crops | C8: 011 | D8: Growing of non-perennial crops
A9: 0121 | B9: Growing of grapes | C9: 012 | D9: Growing of perennial crops
A10: 0122 | B10: Growing of tropical and subtropical fruits | C10: 012 | D10: Growing of perennial crops
A11: 0123 | B11: Growing of citrus fruits | C11: 012 | D11: Growing of perennial crops
A12: 0124 | B12: Growing of pome fruits and stone fruits | C12: 012 | D12: Growing of perennial crops
... A464: 9900 | B464: Activities of extraterritorial organizations and bodies | C464: 990 | D464: Activities of extraterritorial organizations and bodies

Sheet INDUSTRY
A1: INDUSTRY CODE | B1: INDUSTRY | C1: INDUSTRY GROUP CODE | D1: INDUSTRY GROUP
A2: 011 | B2: Growing of non-perennial crops | C2: 01 | D2: Crop and animal production, hunting and related service activities
A3: 012 | B3: Growing of perennial crops | C3: 01 | D3: Crop and animal production, hunting and related service activities
A4: 013 | B4: Plant propagation | C4: 01 | D4: Crop and animal production, hunting and related service activities
A5: 014 | B5: Animal production | C5: 01 | D5: Crop and animal production, hunting and related service activities
A6: 015 | B6: Mixed farming | C6: 01 | D6: Crop and animal production, hunting and related service activities
A7: 016 | B7: Support activities to agriculture and post-harvest crop activities | C7: 01 | D7: Crop and animal production, hunting and related service activities
A8: 017 | B8: Hunting, trapping and related service activities | C8: 01 | D8: Crop and animal production, hunting and related service activities
A9: 021 | B9: Silviculture and other forestry activities | C9: 02 | D9: Forestry and logging
A10: 022 | B10: Logging | C10: 02 | D10: Forestry and logging
A11: 023 | B11: Gathering of non-wood forest products | C11: 02 | D11: Forestry and logging
A12: 024 | B12: Support services to forestry | C12: 02 | D12: Forestry and logging
... A259: 990 | B259: Activities of extraterritorial organizations and bodies | C259: 99 | D259: Activities of extraterritorial organizations and bodies

Sheet INDUSTRYGROUP
A1: INDUSTRY GROUP CODE | B1: INDUSTRY GROUP | C1: SECTOR CODE | D1: SECTOR
A2: 01 | B2: Crop and animal production, hunting and related service activities | C2: A | D2: Agriculture, forestry and fishing
A3: 02 | B3: Forestry and logging | C3: A | D3: Agriculture, forestry and fishing
A4: 03 | B4: Fishing and aquaculture | C4: A | D4: Agriculture, forestry and fishing
A5: 05 | B5: Mining of coal and lignite | C5: B | D5: Mining and quarrying
A6: 06 | B6: Extraction of crude petroleum and natural gas | C6: B | D6: Mining and quarrying
A7: 07 | B7: Mining of metal ores | C7: B | D7: Mining and quarrying
A8: 08 | B8: Other mining and quarrying | C8: B | D8: Mining and quarrying
A9: 09 | B9: Mining support service activities | C9: B | D9: Mining and quarrying
A10: 10 | B10: Manufacture of food products | C10: C | D10: Manufacturing
A11: 11 | B11: Manufacture of beverages | C11: C | D11: Manufacturing
A12: 12 | B12: Manufacture of tobacco products | C12: C | D12: Manufacturing
... A88: 99 | B88: Activities of extraterritorial organizations and bodies | C88: V | D88: Activities of extraterritorial organizations and bodies
C116: CODE | D116: SUB-INDUSTRY
C117: 011 | D117: Growing of non-perennial crops
C118: 012 | D118: Growing of perennial crops
C119: 013 | D119: Plant propagation
C120: 014 | D120: Animal production
C121: 015 | D121: Mixed farming
C122: 016 | D122: Support activities to agriculture and post-harvest crop activities
C123: 017 | D123: Hunting, trapping and related service activities
C124: 021 | D124: Silviculture and other forestry activities
C125: 022 | D125: Logging
C126: 023 | D126: Gathering of non-wood forest products
C127: 024 | D127: Support services to forestry
... C374: 990 | D374: Activities of extraterritorial organizations and bodies

Sheet SECTOR
A1: SECTOR CODE | B1: SECTOR
A2: A | B2: Agriculture, forestry and fishing
A3: B | B3: Mining and quarrying
A4: C | B4: Manufacturing
A5: D | B5: Electricity, gas, steam and air conditioning supply
A6: E | B6: Water supply; sewerage, waste management and remediation activities
A7: F | B7: Construction
A8: G | B8: Wholesale and retail trade
A9: H | B9: Transportation and storage
A10: I | B10: Accommodation and food service activities
A11: J | B11: Publishing, broadcasting, and content production and distribution activities
A12: K | B12: Telecommunications, computer programming, consultancy, computing infrastructure, and other information service activities
... A374: 990 | B374: Activities of extraterritorial organizations and bodies

Sheet ISIC_Rev_5_english_structur (2)
A1: Column1 | B1: Column2 | C1: Column4 | D1: Column5 | E1: Column6 | F1: Column7 | G1: Column8 | H1: Column9 | I1: Column10 | J1: Column11
A2: ISIC Rev 5 Code | B2: ISIC Rev 5 Title | E2: =IF(LEN(ISIC_Rev_5_english_structure__1[[#This Row],[Column1]])=2, A2, "") | F2: =_xlfn.XLOOKUP(LEFT(A2,2),SECTOR!$A$2:$A$88,SECTOR!$B$2:$B$88,"") | G2: =_xlfn.XLOOKUP(LEFT(A2,3),INDUSTRY!$A$2:$A$259,INDUSTRY!$A$2:$A$259,"") | H2: =_xlfn.XLOOKUP(LEFT(A2,3),INDUSTRY!$A$2:$A$259,INDUSTRY!$B$2:$B$259,"") | I2: =IF(LEN(A2)=4,A2,"") | J2: =IF(LEN(A2)=4,B2,"")
A3: A | B3: Agriculture, forestry and fishing | C3: A | D3: =_xlfn.XLOOKUP(ISIC_Rev_5_english_structure__1[[#This Row],[Column4]],INDUSTRYGROUP!$C$2:$C$23,INDUSTRYGROUP!$D$2:$D$23,"NONE") -> Agriculture, forestry and fishing | E3: =_xlfn.XLOOKUP(LEFT(A3,2),SECTOR!$A$2:$A$88,SECTOR!$A$2:$A$88,"") -> A | F3: =_xlfn.XLOOKUP(LEFT(A3,2),SECTOR!$A$2:$A$88,SECTOR!$B$2:$B$88,"") -> Agriculture, forestry and fishing | G3: =_xlfn.XLOOKUP(LEFT(A3,3),INDUSTRY!$A$2:$A$259,INDUSTRY!$A$2:$A$259,"") | H3: =_xlfn.XLOOKUP(LEFT(A3,3),INDUSTRY!$A$2:$A$259,INDUSTRY!$B$2:$B$259,"") | I3: =IF(LEN(A3)=4,A3,"") | J3: =IF(LEN(A3)=4,B3,"")
A4: 01 | B4: Crop and animal production, hunting and related service activities | C4: A | D4: =_xlfn.XLOOKUP(ISIC_Rev_5_english_structure__1[[#This Row],[Column4]],INDUSTRYGROUP!$C$2:$C$23,INDUSTRYGROUP!$D$2:$D$23,"NONE") -> Agriculture, forestry and fishing | E4: =_xlfn.XLOOKUP(LEFT(A4,2),SECTOR!$A$2:$A$88,SECTOR!$A$2:$A$88,"") | F4: =_xlfn.XLOOKUP(LEFT(A4,2),SECTOR!$A$2:$A$88,SECTOR!$B$2:$B$88,"") | G4: =_xlfn.XLOOKUP(LEFT(A4,3),INDUSTRY!$A$2:$A$259,INDUSTRY!$A$2:$A$259,"") | H4: =_xlfn.XLOOKUP(LEFT(A4,3),INDUSTRY!$A$2:$A$259,INDUSTRY!$B$2:$B$259,"") | I4: =IF(LEN(A4)=4,A4,"") | J4: =IF(LEN(A4)=4,B4,"")
A5: 011 | B5: Growing of non-perennial crops | C5: A | D5: =_xlfn.XLOOKUP(ISIC_Rev_5_english_structure__1[[#This Row],[Column4]],INDUSTRYGROUP!$C$2:$C$23,INDUSTRYGROUP!$D$2:$D$23,"NONE") -> Agriculture, forestry and fishing | E5: =_xlfn.XLOOKUP(LEFT(A5,2),SECTOR!$A$2:$A$88,SECTOR!$A$2:$A$88,"") | F5: =_xlfn.XLOOKUP(LEFT(A5,2),SECTOR!$A$2:$A$88,SECTOR!$B$2:$B$88,"") | G5: =_xlfn.XLOOKUP(LEFT(A5,3),INDUSTRY!$A$2:$A$259,INDUSTRY!$A$2:$A$259,"") -> 011 | H5: =_xlfn.XLOOKUP(LEFT(A5,3),INDUSTRY!$A$2:$A$259,INDUSTRY!$B$2:$B$259,"") -> Growing of non-perennial crops | I5: =IF(LEN(A5)=4,A5,"") | J5: =IF(LEN(A5)=4,B5,"")
A6: 0111 | B6: Growing of cereals (except rice), leguminous crops and oil seeds | C6: A | D6: =_xlfn.XLOOKUP(ISIC_Rev_5_english_structure__1[[#This Row],[Column4]],INDUSTRYGROUP!$C$2:$C$23,INDUSTRYGROUP!$D$2:$D$23,"NONE") -> Agriculture, forestry and fishing | E6: =_xlfn.XLOOKUP(LEFT(A6,2),SECTOR!$A$2:$A$88,SECTOR!$A$2:$A$88,"") | F6: =_xlfn.XLOOKUP(LEFT(A6,2),SECTOR!$A$2:$A$88,SECTOR!$B$2:$B$88,"") | G6: =_xlfn.XLOOKUP(LEFT(A6,3),INDUSTRY!$A$2:$A$259,INDUSTRY!$A$2:$A$259,"") -> 011 | H6: =_xlfn.XLOOKUP(LEFT(A6,3),INDUSTRY!$A$2:$A$259,INDUSTRY!$B$2:$B$259,"") -> Growing of non-perennial crops | I6: =IF(LEN(A6)=4,A6,"") -> 0111 | J6: =IF(LEN(A6)=4,B6,"") -> Growing of cereals (except rice), leguminous crops and oil seeds
A7: 0112 | B7: Growing of rice | C7: A | D7: =_xlfn.XLOOKUP(ISIC_Rev_5_english_structure__1[[#This Row],[Column4]],INDUSTRYGROUP!$C$2:$C$23,INDUSTRYGROUP!$D$2:$D$23,"NONE") -> Agriculture, forestry and fishing | E7: =_xlfn.XLOOKUP(LEFT(A7,2),SECTOR!$A$2:$A$88,SECTOR!$A$2:$A$88,"") | F7: =_xlfn.XLOOKUP(LEFT(A7,2),SECTOR!$A$2:$A$88,SECTOR!$B$2:$B$88,"") | G7: =_xlfn.XLOOKUP(LEFT(A7,3),INDUSTRY!$A$2:$A$259,INDUSTRY!$A$2:$A$259,"") -> 011 | H7: =_xlfn.XLOOKUP(LEFT(A7,3),INDUSTRY!$A$2:$A$259,INDUSTRY!$B$2:$B$259,"") -> Growing of non-perennial crops | I7: =IF(LEN(A7)=4,A7,"") -> 0112 | J7: =IF(LEN(A7)=4,B7,"") -> Growing of rice
A8: 0113 | B8: Growing of vegetables and melons, roots and tubers | C8: A | D8: =_xlfn.XLOOKUP(ISIC_Rev_5_english_structure__1[[#This Row],[Column4]],INDUSTRYGROUP!$C$2:$C$23,INDUSTRYGROUP!$D$2:$D$23,"NONE") -> Agriculture, forestry and fishing | E8: =_xlfn.XLOOKUP(LEFT(A8,2),SECTOR!$A$2:$A$88,SECTOR!$A$2:$A$88,"") | F8: =_xlfn.XLOOKUP(LEFT(A8,2),SECTOR!$A$2:$A$88,SECTOR!$B$2:$B$88,"") | G8: =_xlfn.XLOOKUP(LEFT(A8,3),INDUSTRY!$A$2:$A$259,INDUSTRY!$A$2:$A$259,"") -> 011 | H8: =_xlfn.XLOOKUP(LEFT(A8,3),INDUSTRY!$A$2:$A$259,INDUSTRY!$B$2:$B$259,"") -> Growing of non-perennial crops | I8: =IF(LEN(A8)=4,A8,"") -> 0113 | J8: =IF(LEN(A8)=4,B8,"") -> Growing of vegetables and melons, roots and tubers
A9: 0114 | B9: Growing of sugar cane | C9: A | D9: =_xlfn.XLOOKUP(ISIC_Rev_5_english_structure__1[[#This Row],[Column4]],INDUSTRYGROUP!$C$2:$C$23,INDUSTRYGROUP!$D$2:$D$23,"NONE") -> Agriculture, forestry and fishing | E9: =_xlfn.XLOOKUP(LEFT(A9,2),SECTOR!$A$2:$A$88,SECTOR!$A$2:$A$88,"") | F9: =_xlfn.XLOOKUP(LEFT(A9,2),SECTOR!$A$2:$A$88,SECTOR!$B$2:$B$88,"") | G9: =_xlfn.XLOOKUP(LEFT(A9,3),INDUSTRY!$A$2:$A$259,INDUSTRY!$A$2:$A$259,"") -> 011 | H9: =_xlfn.XLOOKUP(LEFT(A9,3),INDUSTRY!$A$2:$A$259,INDUSTRY!$B$2:$B$259,"") -> Growing of non-perennial crops | I9: =IF(LEN(A9)=4,A9,"") -> 0114 | J9: =IF(LEN(A9)=4,B9,"") -> Growing of sugar cane
A10: 0115 | B10: Growing of tobacco | C10: A | D10: =_xlfn.XLOOKUP(ISIC_Rev_5_english_structure__1[[#This Row],[Column4]],INDUSTRYGROUP!$C$2:$C$23,INDUSTRYGROUP!$D$2:$D$23,"NONE") -> Agriculture, forestry and fishing | E10: =_xlfn.XLOOKUP(LEFT(A10,2),SECTOR!$A$2:$A$88,SECTOR!$A$2:$A$88,"") | F10: =_xlfn.XLOOKUP(LEFT(A10,2),SECTOR!$A$2:$A$88,SECTOR!$B$2:$B$88,"") | G10: =_xlfn.XLOOKUP(LEFT(A10,3),INDUSTRY!$A$2:$A$259,INDUSTRY!$A$2:$A$259,"") -> 011 | H10: =_xlfn.XLOOKUP(LEFT(A10,3),INDUSTRY!$A$2:$A$259,INDUSTRY!$B$2:$B$259,"") -> Growing of non-perennial crops | I10: =IF(LEN(A10)=4,A10,"") -> 0115 | J10: =IF(LEN(A10)=4,B10,"") -> Growing of tobacco
A11: 0116 | B11: Growing of fibre crops | C11: A | D11: =_xlfn.XLOOKUP(ISIC_Rev_5_english_structure__1[[#This Row],[Column4]],INDUSTRYGROUP!$C$2:$C$23,INDUSTRYGROUP!$D$2:$D$23,"NONE") -> Agriculture, forestry and fishing | E11: =_xlfn.XLOOKUP(LEFT(A11,2),SECTOR!$A$2:$A$88,SECTOR!$A$2:$A$88,"") | F11: =_xlfn.XLOOKUP(LEFT(A11,2),SECTOR!$A$2:$A$88,SECTOR!$B$2:$B$88,"") | G11: =_xlfn.XLOOKUP(LEFT(A11,3),INDUSTRY!$A$2:$A$259,INDUSTRY!$A$2:$A$259,"") -> 011 | H11: =_xlfn.XLOOKUP(LEFT(A11,3),INDUSTRY!$A$2:$A$259,INDUSTRY!$B$2:$B$259,"") -> Growing of non-perennial crops | I11: =IF(LEN(A11)=4,A11,"") -> 0116 | J11: =IF(LEN(A11)=4,B11,"") -> Growing of fibre crops
A12: 0119 | B12: Growing of other non-perennial crops | C12: A | D12: =_xlfn.XLOOKUP(ISIC_Rev_5_english_structure__1[[#This Row],[Column4]],INDUSTRYGROUP!$C$2:$C$23,INDUSTRYGROUP!$D$2:$D$23,"NONE") -> Agriculture, forestry and fishing | E12: =_xlfn.XLOOKUP(LEFT(A12,2),SECTOR!$A$2:$A$88,SECTOR!$A$2:$A$88,"") | F12: =_xlfn.XLOOKUP(LEFT(A12,2),SECTOR!$A$2:$A$88,SECTOR!$B$2:$B$88,"") | G12: =_xlfn.XLOOKUP(LEFT(A12,3),INDUSTRY!$A$2:$A$259,INDUSTRY!$A$2:$A$259,"") -> 011 | H12: =_xlfn.XLOOKUP(LEFT(A12,3),INDUSTRY!$A$2:$A$259,INDUSTRY!$B$2:$B$259,"") -> Growing of non-perennial crops | I12: =IF(LEN(A12)=4,A12,"") -> 0119 | J12: =IF(LEN(A12)=4,B12,"") -> Growing of other non-perennial crops
A13: 012 | B13: Growing of perennial crops | C13: A | D13: =_xlfn.XLOOKUP(ISIC_Rev_5_english_structure__1[[#This Row],[Column4]],INDUSTRYGROUP!$C$2:$C$23,INDUSTRYGROUP!$D$2:$D$23,"NONE") -> Agriculture, forestry and fishing | E13: =_xlfn.XLOOKUP(LEFT(A13,2),SECTOR!$A$2:$A$88,SECTOR!$A$2:$A$88,"") | F13: =_xlfn.XLOOKUP(LEFT(A13,2),SECTOR!$A$2:$A$88,SECTOR!$B$2:$B$88,"") | G13: =_xlfn.XLOOKUP(LEFT(A13,3),INDUSTRY!$A$2:$A$259,INDUSTRY!$A$2:$A$259,"") -> 012 | H13: =_xlfn.XLOOKUP(LEFT(A13,3),INDUSTRY!$A$2:$A$259,INDUSTRY!$B$2:$B$259,"") -> Growing of perennial crops | I13: =IF(LEN(A13)=4,A13,"") | J13: =IF(LEN(A13)=4,B13,"")
A14: 0121 | B14: Growing of grapes | C14: A | D14: =_xlfn.XLOOKUP(ISIC_Rev_5_english_structure__1[[#This Row],[Column4]],INDUSTRYGROUP!$C$2:$C$23,INDUSTRYGROUP!$D$2:$D$23,"NONE") -> Agriculture, forestry and fishing | E14: =_xlfn.XLOOKUP(LEFT(A14,2),SECTOR!$A$2:$A$88,SECTOR!$A$2:$A$88,"") | F14: =_xlfn.XLOOKUP(LEFT(A14,2),SECTOR!$A$2:$A$88,SECTOR!$B$2:$B$88,"") | G14: =_xlfn.XLOOKUP(LEFT(A14,3),INDUSTRY!$A$2:$A$259,INDUSTRY!$A$2:$A$259,"") -> 012 | H14: =_xlfn.XLOOKUP(LEFT(A14,3),INDUSTRY!$A$2:$A$259,INDUSTRY!$B$2:$B$259,"") -> Growing of perennial crops | I14: =IF(LEN(A14)=4,A14,"") -> 0121 | J14: =IF(LEN(A14)=4,B14,"") -> Growing of grapes
... A832: 9900 | B832: Activities of extraterritorial organizations and bodies | C832: V | D832: =_xlfn.XLOOKUP(ISIC_Rev_5_english_structure__1[[#This Row],[Column4]],INDUSTRYGROUP!$C$2:$C$23,INDUSTRYGROUP!$D$2:$D$23,"NONE") -> NONE | E832: =_xlfn.XLOOKUP(LEFT(A832,2),SECTOR!$A$2:$A$88,SECTOR!$A$2:$A$88,"") | F832: =_xlfn.XLOOKUP(LEFT(A832,2),SECTOR!$A$2:$A$88,SECTOR!$B$2:$B$88,"") | G832: =_xlfn.XLOOKUP(LEFT(A832,3),INDUSTRY!$A$2:$A$259,INDUSTRY!$A$2:$A$259,"") -> 990 | H832: =_xlfn.XLOOKUP(LEFT(A832,3),INDUSTRY!$A$2:$A$259,INDUSTRY!$B$2:$B$259,"") -> Activities of extraterritorial organizations and bodies | I832: =IF(LEN(A832)=4,A832,"") -> 9900 | J832: =IF(LEN(A832)=4,B832,"") -> Activities of extraterritorial organizations and bodies

Sheet ISIC_Rev_5_english_structure (1
A1: ISIC Rev 5 Code,"ISIC Rev 5 Title"
A2: A,"Agriculture, forestry and fishing"
A3: 01,"Crop and animal production, hunting and related service activities"
A4: 011,"Growing of non-perennial crops"
A5: 0111,"Growing of cereals (except rice), leguminous crops and oil seeds"
A6: 0112,"Growing of rice"
A7: 0113,"Growing of vegetables and melons, roots and tubers"
A8: 0114,"Growing of sugar cane"
A9: 0115,"Growing of tobacco"
A10: 0116,"Growing of fibre crops"
A11: 0119,"Growing of other non-perennial crops"
A12: 012,"Growing of perennial crops"
... A119: 1104,"Manufacture of malt"
A120: 1105,"Manufacture of soft drinks | B120: production of mineral waters and other bottled waters"
A121: 12,"Manufacture of tobacco products"
A122: 120,"Manufacture of tobacco products"
A123: 1200,"Manufacture of tobacco products"
A124: 13,"Manufacture of textiles"
A125: 131,"Spinning, weaving and finishing of textiles"
A126: 1311,"Preparation and spinning of textile fibres"
A127: 1312,"Weaving of textiles"
A128: 1313,"Finishing of textiles"
A129: 139,"Manufacture of other textiles"
A130: 1391,"Manufacture of knitted and crocheted fabrics"
A131: 1392,"Manufacture of made-up textile articles, except apparel"
A132: 1393,"Manufacture of carpets and rugs"
... A142: 15,"Manufacture of leather and related products"
A143: 151,"Tanning, dyeing, dressing of leather and fur | B143: manufacture of luggage, handbags, saddlery and harness"
A144: 1511,"Tanning and dressing of leather | B144: dressing and dyeing of fur"
A145: 1512,"Manufacture of luggage, handbags and the like, saddlery and harness of any material"
A146: 152,"Manufacture of footwear"
A147: 1520,"Manufacture of footwear"
A148: 16,"Manufacture of wood and of products of wood and cork, except furniture | B148: manufacture of articles of straw and plaiting materials"
A149: 161,"Sawmilling and planing of wood"
A150: 1610,"Sawmilling and planing of wood"
A151: 162,"Manufacture of products of wood, cork, straw and plaiting materials"
A152: 1621,"Manufacture of veneer sheets and wood-based panels"
A153: 1622,"Manufacture of builders' carpentry and joinery"
A154: 1623,"Manufacture of wooden containers"
A155: 1629,"Manufacture of other products of wood | B155: manufacture of articles of cork, straw and plaiting materials"
...
